Workbook

Sheet Summary
A1: TỔNG QUAN TEST PARA_BANK
A3: Ghi chú | B3: Cập nhật trạng thái ở sheet TestExecution. Summary sẽ tự đếm Pass, Fail, Blocked, Not Run.
A5: Chỉ số | B5: Giá trị | D5: Theo luồng nghiệp vụ | E5: Số lượng
A6: Tổng số test case | B6: =COUNTA(TestCases!A2:A1000) -> 60 | D6: 1. Truy cập và đăng ký | E6: =COUNTIF(TestCases!B:B,D6) -> 7
A7: Smoke | B7: =COUNTIF(TestCases!K:K,"Smoke") -> 3 | D7: 2. Đăng nhập và đăng xuất | E7: =COUNTIF(TestCases!B:B,D7) -> 8
A8: GUI | B8: =COUNTIF(TestCases!K:K,"GUI") -> 17 | D8: 3. Tổng quan tài khoản | E8: =COUNTIF(TestCases!B:B,D8) -> 6
A9: Functional | B9: =COUNTIF(TestCases!K:K,"Functional") -> 40 | D9: 4. Mở tài khoản mới | E9: =COUNTIF(TestCases!B:B,D9) -> 5
A10: Pass | B10: =COUNTIF(TestExecution!F:F,"Pass") -> 0 | D10: 5. Chuyển tiền | E10: =COUNTIF(TestCases!B:B,D10) -> 10
A11: Fail | B11: =COUNTIF(TestExecution!F:F,"Fail") -> 0 | D11: 6. Thanh toán hóa đơn | E11: =COUNTIF(TestCases!B:B,D11) -> 8
A12: Blocked | B12: =COUNTIF(TestExecution!F:F,"Blocked") -> 0 | D12: 7. Tìm giao dịch | E12: =COUNTIF(TestCases!B:B,D12) -> 7
A13: Not Run | B13: =COUNTIF(TestExecution!F:F,"Not Run") -> 60 | D13: 8. Cập nhật thông tin | E13: =COUNTIF(TestCases!B:B,D13) -> 5
A14: Tỷ lệ Pass | B14: =IF((B10+B11+B12+B13)=0,0,B10/(B10+B11+B12+B13)) -> 0 | D14: 9. Yêu cầu vay vốn | E14: =COUNTIF(TestCases!B:B,D14) -> 4

Sheet Scenario
A1: Mã Scenario | B1: Module | C1: Tên Scenario | D1: Điều kiện tiên quyết | E1: Dữ liệu kiểm thử | F1: Kết quả mong đợi | G1: Mức độ ưu tiên | H1: Loại
A2: SC01 | B2: Đăng ký người dùng | C2: Mở trang Đăng ký từ trang Đăng nhập | D2: Người dùng đang ở trang chủ ParaBank | E2: Không có | F2: Trang Đăng ký được mở thành công | G2: Trung bình | H2: GUI
A3: SC02 | B3: Đăng ký người dùng | C3: Đăng ký thành công với thông tin hợp lệ | D3: Người dùng chưa đăng nhập | E3: Thông tin cá nhân hợp lệ, tên đăng nhập chưa tồn tại, mật khẩu hợp lệ | F3: Tài khoản mới được tạo thành công | G3: Cao | H3: Functional
A4: SC03 | B4: Đăng ký người dùng | C4: Đăng ký khi để trống các trường bắt buộc | D4: Người dùng đang ở trang Đăng ký | E4: Để trống các trường bắt buộc | F4: Hệ thống hiển thị thông báo lỗi cho các trường bắt buộc | G4: Cao | H4: Functional
A5: SC04 | B5: Đăng ký người dùng | C5: Đăng ký khi mật khẩu và xác nhận mật khẩu không khớp | D5: Người dùng đang ở trang Đăng ký | E5: Thông tin hợp lệ, mật khẩu và xác nhận mật khẩu khác nhau | F5: Hệ thống từ chối đăng ký và hiển thị thông báo lỗi phù hợp | G5: Cao | H5: Functional
A6: SC05 | B6: Đăng ký người dùng | C6: Đăng ký với tên đăng nhập đã tồn tại | D6: Người dùng đang ở trang Đăng ký | E6: Tên đăng nhập đã tồn tại, các thông tin khác hợp lệ | F6: Hệ thống từ chối đăng ký và báo lỗi tên đăng nhập đã được sử dụng | G6: Cao | H6: Functional
A7: SC06 | B7: Đăng nhập | C7: Kiểm tra ô nhập tên đăng nhập, mật khẩu và nút Đăng nhập hoạt động bình thường | D7: Người dùng đang ở trang Đăng nhập | E7: Dữ liệu nhập hợp lệ | F7: Các ô nhập cho phép nhập dữ liệu và nút Đăng nhập có thể nhấn được | G7: Trung bình | H7: GUI
A8: SC07 | B8: Đăng nhập | C8: Đăng nhập thành công với tài khoản hợp lệ | D8: Người dùng đã có tài khoản đăng ký trước đó | E8: Tên đăng nhập và mật khẩu hợp lệ | F8: Người dùng đăng nhập thành công và được chuyển đến trang Tổng quan tài khoản | G8: Cao | H8: Smoke
A9: SC08 | B9: Đăng nhập | C9: Đăng nhập với tên đăng nhập không hợp lệ | D9: Người dùng đang ở trang Đăng nhập | E9: Tên đăng nhập sai, mật khẩu đúng | F9: Đăng nhập thất bại và hiển thị thông báo lỗi phù hợp | G9: Cao | H9: Functional
A10: SC09 | B10: Đăng nhập | C10: Đăng nhập với mật khẩu không hợp lệ | D10: Người dùng đang ở trang Đăng nhập | E10: Tên đăng nhập đúng, mật khẩu sai | F10: Đăng nhập thất bại và hiển thị thông báo lỗi phù hợp | G10: Cao | H10: Functional
A11: SC10 | B11: Đăng xuất | C11: Đăng xuất sau khi đăng nhập thành công | D11: Người dùng đã đăng nhập | E11: Không có | F11: Người dùng đăng xuất thành công và quay về trang chủ hoặc trang đăng nhập | G11: Cao | H11: Smoke
A12: SC11 | B12: Tổng quan tài khoản | C12: Mở trang Tổng quan tài khoản sau khi đăng nhập | D12: Người dùng đã đăng nhập | E12: Không có | F12: Danh sách tài khoản được hiển thị thành công | G12: Cao | H12: Functional
... A41: SC40 | B41: Yêu cầu vay vốn | C41: Kiểm tra thông báo kết quả vay là duyệt hoặc từ chối | D41: Người dùng vừa gửi yêu cầu vay | E41: Dữ liệu yêu cầu vay hợp lệ | F41: Hệ thống hiển thị rõ kết quả duyệt hoặc từ chối | G41: Trung bình | H41: Functional

Sheet TestCases
A1: Test Case ID | B1: Luồng nghiệp vụ | C1: Module | D1: Tên Test Case | E1: Điều kiện tiên quyết | F1: Data Sheet | G1: Data Set ID | H1: Các bước thực hiện | I1: Kết quả mong đợi | J1: Mức độ ưu tiên | K1: Loại | L1: kết quả
A2: TC01 | B2: 1. Truy cập và đăng ký | C2: Trang chủ / Đăng ký | D2: Hiển thị link Register trên trang chủ | E2: Người dùng mở trang chủ ParaBank | H2: 1. Mở trang chủ ParaBank 2. Quan sát khu vực Customer Login | I2: Link Register hiển thị rõ ràng và có thể sử dụng | J2: Trung bình | K2: GUI | L2: pass
A3: TC02 | B3: 1. Truy cập và đăng ký | C3: Đăng ký | D3: Mở trang Register thành công | E3: Người dùng đang ở trang chủ ParaBank | H3: 1. Mở trang chủ 2. Nhấn Register | I3: Trang Register được mở đúng | J3: Trung bình | K3: GUI | L3: pass
A4: TC03 | B4: 1. Truy cập và đăng ký | C4: Đăng ký | D4: Hiển thị đầy đủ các trường trên form đăng ký | E4: Người dùng đang ở trang Register | H4: 1. Mở trang Register 2. Kiểm tra các trường First Name, Last Name, Address, City, State, Zip Code, Phone, SSN, Username, Password, Confirm | I4: Form đăng ký hiển thị đầy đủ các trường cần thiết | J4: Trung bình | K4: GUI | L4: pass
A5: TC04 | B5: 1. Truy cập và đăng ký | C5: Đăng ký | D5: Đăng ký tài khoản thành công với dữ liệu hợp lệ | E5: Người dùng chưa đăng nhập | F5: TestData_Register | G5: REG_01 | H5: 1. Mở trang Register 2. Nhập đầy đủ dữ liệu hợp lệ 3. Nhấn Register | I5: Tài khoản được tạo thành công, hệ thống chuyển sang trang sau đăng ký hoặc thông báo thành công | J5: Cao | K5: Functional | L5: pass
A6: TC05 | B6: 1. Truy cập và đăng ký | C6: Đăng ký | D6: Đăng ký khi để trống trường bắt buộc | E6: Người dùng đang ở trang Register | F6: TestData_Register | G6: REG_02 | H6: 1. Mở trang Register 2. Để trống các trường bắt buộc 3. Nhấn Register | I6: Hệ thống hiển thị lỗi xác thực cho các trường bắt buộc | J6: Cao | K6: Functional | L6: pass
A7: TC06 | B7: 1. Truy cập và đăng ký | C7: Đăng ký | D7: Đăng ký khi Password và Confirm không khớp | E7: Người dùng đang ở trang Register | F7: TestData_Register | G7: REG_03 | H7: 1. Mở trang Register 2. Nhập thông tin hợp lệ 3. Nhập Password và Confirm khác nhau 4. Nhấn Register | I7: Hệ thống từ chối đăng ký và hiển thị lỗi không khớp mật khẩu | J7: Cao | K7: Functional | L7: pass
A8: TC07 | B8: 1. Truy cập và đăng ký | C8: Đăng ký | D8: Đăng ký với Username đã tồn tại | E8: Username kiểm thử đã tồn tại trên hệ thống | F8: TestData_Register | G8: REG_04 | H8: 1. Mở trang Register 2. Nhập dữ liệu hợp lệ nhưng dùng Username đã tồn tại 3. Nhấn Register | I8: Hệ thống từ chối tạo tài khoản và hiển thị lỗi Username đã tồn tại | J8: Cao | K8: Functional | L8: pass
A9: TC08 | B9: 2. Đăng nhập và đăng xuất | C9: Đăng nhập | D9: Hiển thị ô Username, Password và nút Login | E9: Người dùng mở trang chủ ParaBank | H9: 1. Mở trang chủ ParaBank 2. Kiểm tra khu vực Customer Login | I9: Ô Username, Password và nút Login hiển thị đúng | J9: Trung bình | K9: GUI | L9: pass
A10: TC09 | B10: 2. Đăng nhập và đăng xuất | C10: Đăng nhập | D10: Nhập được dữ liệu vào ô Username và Password | E10: Người dùng đang ở trang chủ ParaBank | F10: TestData_Login | G10: LOGIN_01 | H10: 1. Mở trang chủ 2. Nhập Username 3. Nhập Password | I10: Hai ô nhập nhận dữ liệu bình thường | J10: Trung bình | K10: GUI | L10: pass
A11: TC10 | B11: 2. Đăng nhập và đăng xuất | C11: Đăng nhập | D11: Đăng nhập thành công với tài khoản hợp lệ | E11: Người dùng đã có tài khoản hợp lệ | F11: TestData_Login | G11: LOGIN_01 | H11: 1. Mở trang chủ 2. Nhập Username hợp lệ 3. Nhập Password hợp lệ 4. Nhấn Login | I11: Đăng nhập thành công và chuyển đến trang Accounts Overview | J11: Cao | K11: Smoke | L11: pass
A12: TC11 | B12: 2. Đăng nhập và đăng xuất | C12: Đăng nhập | D12: Đăng nhập với Username sai | E12: Người dùng đang ở trang chủ ParaBank | F12: TestData_Login | G12: LOGIN_02 | H12: 1. Mở trang chủ 2. Nhập Username sai 3. Nhập Password 4. Nhấn Login | I12: Hệ thống từ chối đăng nhập và hiển thị lỗi phù hợp | J12: Cao | K12: Functional | L12: pass
A13: TC12 | B13: 2. Đăng nhập và đăng xuất | C13: Đăng nhập | D13: Đăng nhập với Password sai | E13: Người dùng đang ở trang chủ ParaBank | F13: TestData_Login | G13: LOGIN_03 | H13: 1. Mở trang chủ 2. Nhập Username đúng 3. Nhập Password sai 4. Nhấn Login | I13: Hệ thống từ chối đăng nhập và hiển thị lỗi phù hợp | J13: Cao | K13: Functional | L13: pass
A14: TC13 | B14: 2. Đăng nhập và đăng xuất | C14: Đăng nhập | D14: Đăng nhập khi để trống Username và Password | E14: Người dùng đang ở trang chủ ParaBank | F14: TestData_Login | G14: LOGIN_04 | H14: 1. Mở trang chủ 2. Để trống Username và Password 3. Nhấn Login | I14: Hệ thống không cho đăng nhập, hiển thị lỗi phù hợp | J14: Cao | K14: Functional | L14: pass
A15: TC14 | B15: 2. Đăng nhập và đăng xuất | C15: Đăng xuất | D15: Đăng xuất thành công | E15: Người dùng đã đăng nhập | H15: 1. Đăng nhập thành công 2. Nhấn Log Out | I15: Người dùng bị đăng xuất và quay về trang chủ hoặc trang login | J15: Cao | K15: Smoke | L15: pass
A16: TC15 | B16: 2. Đăng nhập và đăng xuất | C16: Bảo mật sau đăng xuất | D16: Không truy cập được trang nội bộ sau khi đăng xuất | E16: Người dùng vừa đăng xuất | H16: 1. Đăng nhập 2. Đăng xuất 3. Nhập trực tiếp URL trang nội bộ như Accounts Overview | I16: Hệ thống yêu cầu đăng nhập lại hoặc chặn truy cập | J16: Cao | K16: Functional | L16: pass
A17: TC16 | B17: 3. Tổng quan tài khoản | C17: Tổng quan tài khoản | D17: Hiển thị menu Account Services sau khi đăng nhập | E17: Người dùng đã đăng nhập | H17: 1. Đăng nhập thành công 2. Quan sát menu bên trái | I17: Menu Account Services hiển thị các mục liên quan tài khoản | J17: Trung bình | K17: GUI | L17: pass
A18: TC17 | B18: 3. Tổng quan tài khoản | C18: Tổng quan tài khoản | D18: Mở trang Accounts Overview thành công | E18: Người dùng đã đăng nhập | H18: 1. Đăng nhập 2. Nhấn Accounts Overview | I18: Trang Accounts Overview được mở thành công | J18: Cao | K18: Functional | L18: pass
A19: TC18 | B19: 3. Tổng quan tài khoản | C19: Tổng quan tài khoản | D19: Hiển thị danh sách tài khoản, số dư, số dư khả dụng | E19: Người dùng đã đăng nhập và có ít nhất 1 tài khoản | H19: 1. Đăng nhập 2. Mở Accounts Overview 3. Quan sát bảng tài khoản | I19: Danh sách tài khoản, Balance, Available Amount hiển thị đúng định dạng | J19: Trung bình | K19: Functional | L19: fail
A20: TC19 | B20: 3. Tổng quan tài khoản | C20: Tổng quan tài khoản | D20: Mở trang chi tiết tài khoản khi nhấn vào số tài khoản | E20: Người dùng đang ở Accounts Overview | H20: 1. Đăng nhập 2. Mở Accounts Overview 3. Nhấn vào một account number | I20: Trang chi tiết tài khoản tương ứng được mở | J20: Trung bình | K20: GUI | L20: pass
A21: TC20 | B21: 3. Tổng quan tài khoản | C21: Tổng quan tài khoản | D21: Hiển thị lịch sử giao dịch trong trang chi tiết tài khoản | E21: Người dùng có ít nhất 1 tài khoản đã phát sinh giao dịch | H21: 1. Đăng nhập 2. Mở Accounts Overview 3. Nhấn vào tài khoản có giao dịch | I21: Lịch sử giao dịch của tài khoản được hiển thị | J21: Trung bình | K21: Functional | L21: pass
A22: TC21 | B22: 3. Tổng quan tài khoản | C22: Tổng quan tài khoản | D22: Hiển thị các cột ngày, loại giao dịch, số tiền trong transaction list | E22: Người dùng đang ở trang chi tiết tài khoản | H22: 1. Mở chi tiết tài khoản 2. Kiểm tra bảng transaction | I22: Bảng giao dịch hiển thị đủ cột cần thiết | J22: Trung bình | K22: GUI | L22: pass
A23: TC22 | B23: 4. Mở tài khoản mới | C23: Mở tài khoản mới | D23: Mở trang Open New Account thành công | E23: Người dùng đã đăng nhập | H23: 1. Đăng nhập 2. Nhấn Open New Account | I23: Trang Open New Account được mở thành công | J23: Trung bình | K23: GUI | L23: pass
A24: TC23 | B24: 4. Mở tài khoản mới | C24: Mở tài khoản mới | D24: Tạo mới tài khoản Checking thành công | E24: Người dùng đã đăng nhập và có tài khoản nguồn | F24: TestData_OpenAccount | G24: OPEN_01 | H24: 1. Đăng nhập 2. Mở Open New Account 3. Chọn Checking 4. Chọn From Account 5. Nhấn Open New Account | I24: Hệ thống tạo tài khoản Checking mới thành công | J24: Cao | K24: Functional | L24: pass
A25: TC24 | B25: 4. Mở tài khoản mới | C25: Mở tài khoản mới | D25: Tạo mới tài khoản Savings thành công | E25: Người dùng đã đăng nhập và có tài khoản nguồn | F25: TestData_OpenAccount | G25: OPEN_02 | H25: 1. Đăng nhập 2. Mở Open New Account 3. Chọn Savings 4. Chọn From Account 5. Nhấn Open New Account | I25: Hệ thống tạo tài khoản Savings mới thành công | J25: Cao | K25: Functional | L25: pass
A26: TC25 | B26: 4. Mở tài khoản mới | C26: Mở tài khoản mới | D26: Tài khoản mới xuất hiện trong Accounts Overview | E26: Người dùng vừa tạo tài khoản mới thành công | F26: TestData_OpenAccount | G26: OPEN_01 | H26: 1. Tạo tài khoản mới 2. Mở Accounts Overview | I26: Tài khoản vừa tạo xuất hiện trong danh sách tài khoản | J26: Cao | K26: Functional | L26: fail
A27: TC26 | B27: 4. Mở tài khoản mới | C27: Mở tài khoản mới | D27: Mở được chi tiết của tài khoản vừa tạo | E27: Người dùng vừa tạo tài khoản mới thành công | F27: TestData_OpenAccount | G27: OPEN_01 | H27: 1. Tạo tài khoản mới 2. Mở Accounts Overview 3. Nhấn vào tài khoản vừa tạo | I27: Trang chi tiết của tài khoản mới được mở đúng | J27: Trung bình | K27: Functional | L27: fail
A28: TC27 | B28: 5. Chuyển tiền | C28: Chuyển tiền | D28: Mở trang Transfer Funds thành công | E28: Người dùng đã đăng nhập và có ít nhất 2 tài khoản | H28: 1. Đăng nhập 2. Nhấn Transfer Funds | I28: Trang Transfer Funds được mở thành công | J28: Trung bình | K28: GUI | L28: pass
A29: TC28 | B29: 5. Chuyển tiền | C29: Chuyển tiền | D29: Hiển thị đầy đủ form chuyển tiền | E29: Người dùng đang ở Transfer Funds | H29: 1. Mở Transfer Funds 2. Kiểm tra Amount, From Account, To Account, nút Transfer | I29: Form chuyển tiền hiển thị đầy đủ và thao tác được | J29: Trung bình | K29: GUI | L29: pass
A30: TC29 | B30: 5. Chuyển tiền | C30: Chuyển tiền | D30: Chuyển tiền thành công từ tài khoản A sang tài khoản B | E30: Người dùng có ít nhất 2 tài khoản | F30: TestData_Transfer | G30: TRF_01 | H30: 1. Đăng nhập 2. Mở Transfer Funds 3. Chọn From Account=A 4. Chọn To Account=B 5. Nhập 100 6. Nhấn Transfer | I30: Giao dịch chuyển tiền thành công và hiển thị xác nhận | J30: Cao | K30: Smoke | L30: pass
A31: TC30 | B31: 5. Chuyển tiền | C31: Chuyển tiền | D31: Chuyển tiền thành công theo chiều ngược lại từ B sang A | E31: Người dùng có ít nhất 2 tài khoản | F31: TestData_Transfer | G31: TRF_02 | H31: 1. Mở Transfer Funds 2. Chọn From Account=B 3. Chọn To Account=A 4. Nhập 50 5. Nhấn Transfer | I31: Giao dịch chuyển tiền thành công | J31: Cao | K31: Functional | L31: pass
A32: TC31 | B32: 5. Chuyển tiền | C32: Chuyển tiền | D32: Chuyển tiền khi để trống Amount | E32: Người dùng đang ở Transfer Funds | F32: TestData_Transfer | G32: TRF_03 | H32: 1. Mở Transfer Funds 2. Chọn From Account 3. Chọn To Account 4. Để trống Amount 5. Nhấn Transfer | I32: Hệ thống từ chối giao dịch hoặc hiển thị lỗi phù hợp | J32: Cao | K32: Functional | L32: fail
A33: TC32 | B33: 5. Chuyển tiền | C33: Chuyển tiền | D33: Chuyển tiền với Amount sai định dạng | E33: Người dùng đang ở Transfer Funds | F33: TestData_Transfer | G33: TRF_04 | H33: 1. Mở Transfer Funds 2. Chọn tài khoản nguồn, đích 3. Nhập Amount là chữ 4. Nhấn Transfer | I33: Hệ thống từ chối giao dịch hoặc hiển thị lỗi phù hợp | J33: Cao | K33: Functional | L33: fail
A34: TC33 | B34: 5. Chuyển tiền | C34: Chuyển tiền | D34: Chuyển tiền với Amount bằng 0 hoặc âm | E34: Người dùng đang ở Transfer Funds | F34: TestData_Transfer | G34: TRF_05 | H34: 1. Mở Transfer Funds 2. Chọn tài khoản nguồn, đích 3. Nhập 0 hoặc số âm 4. Nhấn Transfer | I34: Hệ thống từ chối giao dịch hoặc hiển thị lỗi phù hợp | J34: Cao | K34: Functional | L34: fail
A35: TC34 | B35: 5. Chuyển tiền | C35: Chuyển tiền | D35: Chọn cùng một tài khoản cho nguồn và đích | E35: Người dùng đang ở Transfer Funds | F35: TestData_Transfer | G35: TRF_06 | H35: 1. Mở Transfer Funds 2. Chọn cùng một tài khoản cho From và To 3. Nhập Amount 4. Nhấn Transfer | I35: Hệ thống chặn giao dịch hoặc thông báo không hợp lệ | J35: Trung bình | K35: Functional | L35: fail
A36: TC35 | B36: 5. Chuyển tiền | C36: Chuyển tiền | D36: Hiển thị thông tin xác nhận sau khi chuyển tiền thành công | E36: Người dùng vừa chuyển tiền thành công | F36: TestData_Transfer | G36: TRF_01 | H36: 1. Thực hiện giao dịch chuyển tiền thành công 2. Quan sát trang kết quả | I36: Trang kết quả hiển thị thông tin xác nhận giao dịch | J36: Trung bình | K36: Functional | L36: pass
A37: TC36 | B37: 5. Chuyển tiền | C37: Chuyển tiền | D37: Cập nhật số dư sau khi chuyển tiền thành công | E37: Người dùng vừa chuyển tiền thành công | F37: TestData_Transfer | G37: TRF_01 | H37: 1. Chuyển tiền thành công 2. Mở Accounts Overview | I37: Số dư các tài khoản được cập nhật tương ứng | J37: Trung bình | K37: Functional
A38: TC37 | B38: 6. Thanh toán hóa đơn | C38: Thanh toán hóa đơn | D38: Mở trang Bill Pay thành công | E38: Người dùng đã đăng nhập | H38: 1. Đăng nhập 2. Nhấn Bill Pay | I38: Trang Bill Pay được mở thành công | J38: Trung bình | K38: GUI | L38: pass
A39: TC38 | B39: 6. Thanh toán hóa đơn | C39: Thanh toán hóa đơn | D39: Hiển thị đầy đủ các trường trên form Bill Pay | E39: Người dùng đang ở Bill Pay | H39: 1. Mở Bill Pay 2. Kiểm tra Payee Name, Address, City, State, Zip Code, Phone, Account, Verify Account, Amount | I39: Form Bill Pay hiển thị đầy đủ các trường cần thiết | J39: Trung bình | K39: GUI | L39: pass
A40: TC39 | B40: 6. Thanh toán hóa đơn | C40: Thanh toán hóa đơn | D40: Thanh toán hóa đơn thành công với dữ liệu hợp lệ | E40: Người dùng đã đăng nhập và có ít nhất 1 tài khoản | F40: TestData_BillPay | G40: BILL_01 | H40: 1. Đăng nhập 2. Mở Bill Pay 3. Nhập đầy đủ dữ liệu hợp lệ 4. Nhấn Send Payment | I40: Hệ thống xử lý thanh toán hóa đơn thành công | J40: Cao | K40: Functional | L40: pass
...

Sheet TestExecution
A1: Run ID | B1: Test Case ID | C1: Data Sheet | D1: Data Set ID | E1: Module | F1: Trạng thái | G1: Kết quả thực tế | H1: Screenshot Path | I1: Bug ID | J1: Trình duyệt | K1: Ghi chú
A2: RUN_001 | B2: TC01 | C2: =IFERROR(VLOOKUP($B2,TestCases!$A$2:$K$61,6,FALSE),"") -> 0 | D2: =IFERROR(VLOOKUP($B2,TestCases!$A$2:$K$61,7,FALSE),"") -> 0 | E2: =IFERROR(VLOOKUP($B2,TestCases!$A$2:$K$61,3,FALSE),"") -> Trang chủ / Đăng ký | F2: Pass | G2: Link Register hiển thị rõ ràng và có thể sử dụng | H2: C:\Users\Admin\Downloads\SeleniumParaBankTest_clean_refactored\bin\Debug\net8.0\Reports\Screenshots\2026-03-27\TC01_Pass_20260327_014257.png | J2: Chrome
A3: RUN_002 | B3: TC02 | C3: =IFERROR(VLOOKUP($B3,TestCases!$A$2:$K$61,6,FALSE),"") -> 0 | D3: =IFERROR(VLOOKUP($B3,TestCases!$A$2:$K$61,7,FALSE),"") -> 0 | E3: =IFERROR(VLOOKUP($B3,TestCases!$A$2:$K$61,3,FALSE),"") -> Đăng ký | F3: Pass | G3: Mở trang Register thành công | H3: C:\Users\Admin\Downloads\SeleniumParaBankTest_clean_refactored\bin\Debug\net8.0\Reports\Screenshots\2026-03-27\TC02_Pass_20260327_014302.png | J3: Chrome
A4: RUN_003 | B4: TC03 | C4: =IFERROR(VLOOKUP($B4,TestCases!$A$2:$K$61,6,FALSE),"") -> 0 | D4: =IFERROR(VLOOKUP($B4,TestCases!$A$2:$K$61,7,FALSE),"") -> 0 | E4: =IFERROR(VLOOKUP($B4,TestCases!$A$2:$K$61,3,FALSE),"") -> Đăng ký | F4: Pass | G4: Form đăng ký hiển thị đủ trường | H4: C:\Users\Admin\Downloads\SeleniumParaBankTest_clean_refactored\bin\Debug\net8.0\Reports\Screenshots\2026-03-27\TC03_Pass_20260327_014307.png | J4: Chrome
A5: RUN_004 | B5: TC04 | C5: =IFERROR(VLOOKUP($B5,TestCases!$A$2:$K$61,6,FALSE),"") -> TestData_Register | D5: =IFERROR(VLOOKUP($B5,TestCases!$A$2:$K$61,7,FALSE),"") -> REG_01 | E5: =IFERROR(VLOOKUP($B5,TestCases!$A$2:$K$61,3,FALSE),"") -> Đăng ký | F5: Pass | G5: Đăng ký tài khoản thành công | H5: C:\Users\Admin\Downloads\SeleniumParaBankTest_clean_refactored\bin\Debug\net8.0\Reports\Screenshots\2026-03-27\TC04_Pass_20260327_014313.png | J5: Chrome
A6: RUN_005 | B6: TC05 | C6: =IFERROR(VLOOKUP($B6,TestCases!$A$2:$K$61,6,FALSE),"") -> TestData_Register | D6: =IFERROR(VLOOKUP($B6,TestCases!$A$2:$K$61,7,FALSE),"") -> REG_02 | E6: =IFERROR(VLOOKUP($B6,TestCases!$A$2:$K$61,3,FALSE),"") -> Đăng ký | F6: Pass | G6: Hiển thị lỗi bắt buộc đúng mong đợi | H6: C:\Users\Admin\Downloads\SeleniumParaBankTest_clean_refactored\bin\Debug\net8.0\Reports\Screenshots\2026-03-27\TC05_Pass_20260327_014319.png | J6: Chrome
A7: RUN_006 | B7: TC06 | C7: =IFERROR(VLOOKUP($B7,TestCases!$A$2:$K$61,6,FALSE),"") -> TestData_Register | D7: =IFERROR(VLOOKUP($B7,TestCases!$A$2:$K$61,7,FALSE),"") -> REG_03 | E7: =IFERROR(VLOOKUP($B7,TestCases!$A$2:$K$61,3,FALSE),"") -> Đăng ký | F7: Pass | G7: Hiển thị lỗi mật khẩu không khớp | H7: C:\Users\Admin\Downloads\SeleniumParaBankTest_clean_refactored\bin\Debug\net8.0\Reports\Screenshots\2026-03-27\TC06_Pass_20260327_014326.png | J7: Chrome
A8: RUN_007 | B8: TC07 | C8: =IFERROR(VLOOKUP($B8,TestCases!$A$2:$K$61,6,FALSE),"") -> TestData_Register | D8: =IFERROR(VLOOKUP($B8,TestCases!$A$2:$K$61,7,FALSE),"") -> REG_04 | E8: =IFERROR(VLOOKUP($B8,TestCases!$A$2:$K$61,3,FALSE),"") -> Đăng ký | F8: Pass | G8: Hiển thị lỗi username đã tồn tại | H8: C:\Users\Admin\Downloads\SeleniumParaBankTest_clean_refactored\bin\Debug\net8.0\Reports\Screenshots\2026-03-27\TC07_Pass_20260327_014333.png | J8: Chrome
A9: RUN_008 | B9: TC08 | C9: =IFERROR(VLOOKUP($B9,TestCases!$A$2:$K$61,6,FALSE),"") -> 0 | D9: =IFERROR(VLOOKUP($B9,TestCases!$A$2:$K$61,7,FALSE),"") -> 0 | E9: =IFERROR(VLOOKUP($B9,TestCases!$A$2:$K$61,3,FALSE),"") -> Đăng nhập | F9: Pass | G9: Hiển thị Username, Password và nút Login | H9: C:\Users\Admin\Downloads\SeleniumParaBankTest_clean_refactored\bin\Debug\net8.0\Reports\Screenshots\2026-03-27\TC08_Pass_20260327_014337.png | J9: Chrome
A10: RUN_009 | B10: TC09 | C10: =IFERROR(VLOOKUP($B10,TestCases!$A$2:$K$61,6,FALSE),"") -> TestData_Login | D10: =IFERROR(VLOOKUP($B10,TestCases!$A$2:$K$61,7,FALSE),"") -> LOGIN_01 | E10: =IFERROR(VLOOKUP($B10,TestCases!$A$2:$K$61,3,FALSE),"") -> Đăng nhập | F10: Pass | G10: Nhập được dữ liệu vào ô Username và Password | H10: C:\Users\Admin\Downloads\SeleniumParaBankTest_clean_refactored\bin\Debug\net8.0\Reports\Screenshots\2026-03-27\TC09_Pass_20260327_014343.png | J10: Chrome
A11: RUN_010 | B11: TC10 | C11: =IFERROR(VLOOKUP($B11,TestCases!$A$2:$K$61,6,FALSE),"") -> TestData_Login | D11: =IFERROR(VLOOKUP($B11,TestCases!$A$2:$K$61,7,FALSE),"") -> LOGIN_01 | E11: =IFERROR(VLOOKUP($B11,TestCases!$A$2:$K$61,3,FALSE),"") -> Đăng nhập | F11: Pass | G11: Đăng nhập thành công | H11: C:\Users\Admin\Downloads\SeleniumParaBankTest_clean_refactored\bin\Debug\net8.0\Reports\Screenshots\2026-03-27\TC10_Pass_20260327_014348.png | J11: Chrome
A12: RUN_011 | B12: TC11 | C12: =IFERROR(VLOOKUP($B12,TestCases!$A$2:$K$61,6,FALSE),"") -> TestData_Login | D12: =IFERROR(VLOOKUP($B12,TestCases!$A$2:$K$61,7,FALSE),"") -> LOGIN_02 | E12: =IFERROR(VLOOKUP($B12,TestCases!$A$2:$K$61,3,FALSE),"") -> Đăng nhập | F12: Pass | G12: Đăng nhập bị từ chối đúng mong đợi | H12: C:\Users\Admin\Downloads\SeleniumParaBankTest_clean_refactored\bin\Debug\net8.0\Reports\Screenshots\2026-03-27\TC11_Pass_20260327_014353.png | J12: Chrome
A13: RUN_012 | B13: TC12 | C13: =IFERROR(VLOOKUP($B13,TestCases!$A$2:$K$61,6,FALSE),"") -> TestData_Login | D13: =IFERROR(VLOOKUP($B13,TestCases!$A$2:$K$61,7,FALSE),"") -> LOGIN_03 | E13: =IFERROR(VLOOKUP($B13,TestCases!$A$2:$K$61,3,FALSE),"") -> Đăng nhập | F13: Pass | G13: Đăng nhập bị từ chối đúng mong đợi | H13: C:\Users\Admin\Downloads\SeleniumParaBankTest_clean_refactored\bin\Debug\net8.0\Reports\Screenshots\2026-03-27\TC12_Pass_20260327_014358.png | J13: Chrome
... A61: RUN_060 | B61: TC60 | C61: =IFERROR(VLOOKUP($B61,TestCases!$A$2:$K$61,6,FALSE),"") -> TestData_RequestLoan | D61: =IFERROR(VLOOKUP($B61,TestCases!$A$2:$K$61,7,FALSE),"") -> LOAN_03 | E61: =IFERROR(VLOOKUP($B61,TestCases!$A$2:$K$61,3,FALSE),"") -> Yêu cầu vay vốn | F61: Fail | G61: Yêu cầu vay thành công ngoài mong đợi | H61: C:\Users\Admin\Downloads\SeleniumParaBankTest_clean_refactored\bin\Debug\net8.0\Reports\Screenshots\2026-03-27\TC60_Fail_20260327_014908.png | J61: Chrome

Sheet TestData_Login
A1: Data Set ID | B1: Username | C1: Password | D1: Kỳ vọng
A2: LOGIN_01 | B2: user_hople_01 | C2: 123456 | D2: Pass
A3: LOGIN_02 | B3: sai_user | C3: 123456 | D3: Fail
A4: LOGIN_03 | B4: user_hople_01 | C4: sai_pass | D4: Fail
A5: LOGIN_04 | D5: Fail

Sheet TestData_Register
A1: Data Set ID | B1: FirstName | C1: LastName | D1: Address | E1: City | F1: State | G1: ZipCode | H1: Phone | I1: SSN | J1: Username | K1: Password | L1: ConfirmPassword | M1: Kỳ vọng
A2: REG_01 | B2: An | C2: Nguyen | D2: 123 Le Loi | E2: HCM | F2: HCM | G2: 700000 | H2: 0901234567 | I2: 123456 | J2: user_moi_01 | K2: 123456 | L2: 123456 | M2: Pass
A3: REG_02 | C3: Nguyen | D3: 123 Le Loi | E3: HCM | F3: HCM | G3: 700000 | H3: 0901234567 | I3: 123456 | K3: 123456 | L3: 123456 | M3: Fail
A4: REG_03 | B4: An | C4: Nguyen | D4: 123 Le Loi | E4: HCM | F4: HCM | G4: 700000 | H4: 0901234567 | I4: 123456 | J4: user_moi_02 | K4: 123456 | L4: 654321 | M4: Fail
A5: REG_04 | B5: An | C5: Nguyen | D5: 123 Le Loi | E5: HCM | F5: HCM | G5: 700000 | H5: 0901234567 | I5: 123456 | J5: user_da_ton_tai | K5: 123456 | L5: 123456 | M5: Fail

Sheet TestData_OpenAccount
A1: Data Set ID | B1: AccountType | C1: FromAccount | D1: Kỳ vọng
A2: OPEN_01 | B2: CHECKING | C2: ACCOUNT_A | D2: Pass
A3: OPEN_02 | B3: SAVINGS | C3: ACCOUNT_A | D3: Pass

Sheet TestData_Transfer
A1: Data Set ID | B1: FromAccount | C1: ToAccount | D1: Amount | E1: Kỳ vọng
A2: TRF_01 | B2: ACCOUNT_A | C2: ACCOUNT_B | D2: 100 | E2: Pass
A3: TRF_02 | B3: ACCOUNT_B | C3: ACCOUNT_A | D3: 50 | E3: Pass
A4: TRF_03 | B4: ACCOUNT_A | C4: ACCOUNT_B | E4: Fail
A5: TRF_04 | B5: ACCOUNT_A | C5: ACCOUNT_B | D5: abc | E5: Fail
A6: TRF_05 | B6: ACCOUNT_A | C6: ACCOUNT_B | D6: 0 / -100 | E6: Fail
A7: TRF_06 | B7: ACCOUNT_A | C7: ACCOUNT_A | D7: 100 | E7: Fail

Sheet TestData_BillPay
A1: Data Set ID | B1: PayeeName | C1: Address | D1: City | E1: State | F1: ZipCode | G1: Phone | H1: Account | I1: VerifyAccount | J1: Amount | K1: Kỳ vọng
A2: BILL_01 | B2: Dien Luc | C2: 45 Tran Hung Dao | D2: HCM | E2: HCM | F2: 700000 | G2: 0908888888 | H2: 12345678 | I2: 12345678 | J2: 200 | K2: Pass
A3: BILL_02 | C3: 45 Tran Hung Dao | D3: HCM | E3: HCM | F3: 700000 | G3: 0908888888 | J3: 200 | K3: Fail
A4: BILL_03 | B4: Dien Luc | C4: 45 Tran Hung Dao | D4: HCM | E4: HCM | F4: 700000 | G4: 0908888888 | H4: 12345678 | I4: 87654321 | J4: 200 | K4: Fail
A5: BILL_04 | B5: Dien Luc | C5: 45 Tran Hung Dao | D5: HCM | E5: HCM | F5: 700000 | G5: 0908888888 | H5: 12345678 | I5: 12345678 | J5: abc | K5: Fail
A6: BILL_05 | B6: Dien Luc | C6: 45 Tran Hung Dao | D6: HCM | E6: HCM | F6: 700000 | G6: 0908888888 | H6: 12345678 | I6: 12345678 | J6: 0 / -50 | K6: Fail

Sheet TestData_FindTransactions
A1: Data Set ID | B1: Account | C1: Date | D1: FromDate | E1: ToDate | F1: Amount | G1: Kỳ vọng
A2: FIND_01 | B2: ACCOUNT_A | C2: 2026-03-01 | G2: Pass
A3: FIND_02 | B3: ACCOUNT_A | D3: 2026-03-01 | E3: 2026-03-10 | G3: Pass
A4: FIND_03 | B4: ACCOUNT_A | F4: 100 | G4: Pass
A5: FIND_04 | B5: ACCOUNT_A | C5: 2099-01-01 | G5: Fail
A6: FIND_05 | B6: ACCOUNT_A | D6: 2026-03-10 | E6: 2026-03-01 | G6: Fail

Sheet TestData_UpdateContact
A1: Data Set ID | B1: Address | C1: City | D1: State | E1: ZipCode | F1: Phone | G1: Kỳ vọng
A2: UPD_01 | B2: 12 Nguyen Hue | C2: HCM | D2: HCM | E2: 700000 | F2: 0909999999 | G2: Pass
A3: UPD_02 | C3: HCM | D3: HCM | E3: 700000 | F3: 0909999999 | G3: Fail
A4: UPD_03 | B4: 12 Nguyen Hue | C4: HCM | D4: HCM | E4: 700000 | F4: 0909999999 | G4: Pass

Sheet TestData_RequestLoan
A1: Data Set ID | B1: LoanAmount | C1: DownPayment | D1: FromAccount | E1: Kỳ vọng
A2: LOAN_01 | B2: 1000 | C2: 200 | D2: ACCOUNT_A | E2: Pass
A3: LOAN_02 | D3: ACCOUNT_A | E3: Fail
A4: LOAN_03 | B4: abc / -100 | C4: xyz / -50 | D4: ACCOUNT_A | E4: Fail
